Workbook
Name UPDATE: 'Data Sheet'!$E$1

Sheet ASSUMPTIONS
G3: ASSUMPTIONS
B5: 1 | C5: TAX RATE IS CONSIDERED TO 27.00% FOR ALL FIRMS
B6: 2 | C6: FOR FORECASTING OF PROFIT & LOSS, BALANCE SHEET, CASH FLOW I AM USING FORECAST FUNCTIONS OF EXCEL
B7: 3 | C7: LEVERED BETA FOR ALL FIRMS IS TAKEN FROM GOOGLE (5 YEAR MONTHLY)
B8: 4 | C8: THE PRE TAX COST OF DEBT IS CALCULATED BY DIVIDING THE INTEREST EXPENSE OF LAST HISTORICAL YEAR FROM PROFIT & LOSS TO CURRENT TOTAL DEBT OF COMPANY
B9: 5 | C9: RISK FREE RATE ON 10-YEAR GOVERNMENT OF INDIA BOND YIELD IS APPROXIMATLY 6.75%.
B10: 6 | C10: INFY ANNUAL AVERAGE RETURN IS 5.73%
B11: 7 | C11: IN NET CAPEX I AM ONLY CONSIDERING FIXED ASSESTS PURCHASED BECAUSE THERE IS DATA AVAILABLE FOR FIXED ASSESTS SOLD
B12: 8 | C12: MARGINAL TAX RATE IS CONSIDERED TO 25.00%
B13: 9 | C13: TERMINAL GROWTH IS 5.75%

Sheet FINANCIAL MODEL<

Sheet Profit & Loss
A1: ='Data Sheet'!B1 -> INFOSYS LTD | H1: =UPDATE
A3: Narration | B3: ='Data Sheet'!B16 -> 42825 | C3: ='Data Sheet'!C16 -> 43190 | D3: ='Data Sheet'!D16 -> 43555 | E3: ='Data Sheet'!E16 -> 43921 | F3: ='Data Sheet'!F16 -> 44286 | G3: ='Data Sheet'!G16 -> 44651 | H3: ='Data Sheet'!H16 -> 45016 | I3: ='Data Sheet'!I16 -> 45382 | ... K3: ='Data Sheet'!K16 -> 46112 | L3: 46473 | M3: 46840 | N3: 47206 | O3: 47572 | P3: 47938
A4: Sales | B4: =IFERROR('Data Sheet'!B17,0) -> 68484 | C4: =IFERROR('Data Sheet'!C17,0) -> 70522 | D4: =IFERROR('Data Sheet'!D17,0) -> 82675 | E4: =IFERROR('Data Sheet'!E17,0) -> 90791 | F4: =IFERROR('Data Sheet'!F17,0) -> 100472 | G4: =IFERROR('Data Sheet'!G17,0) -> 121641 | H4: =IFERROR('Data Sheet'!H17,0) -> 146767 | I4: =IFERROR('Data Sheet'!I17,0) -> 153670 | ... K4: =IFERROR('Data Sheet'!K17,0) -> 178650 | L4: =IFERROR(FORECASTING!D15,0) -> 190427.6 | M4: =IFERROR(FORECASTING!D16,0) -> 203656.95 | N4: =IFERROR(FORECASTING!D17,0) -> 216886.29 | O4: =IFERROR(FORECASTING!D18,0) -> 230115.64 | P4: =IFERROR(FORECASTING!D19,0) -> 243344.98
A6: Expenses | B6: =IFERROR(SUM('Data Sheet'!B18,'Data Sheet'!B20:B22, -1*'Data Sheet'!B19),0) -> 44609 | C6: =IFERROR(SUM('Data Sheet'!C18,'Data Sheet'!C20:C22, -1*'Data Sheet'!C19),0) -> 46395 | D6: =IFERROR(SUM('Data Sheet'!D18,'Data Sheet'!D20:D22, -1*'Data Sheet'!D19),0) -> 55446 | E6: =IFERROR(SUM('Data Sheet'!E18,'Data Sheet'!E20:E22, -1*'Data Sheet'!E19),0) -> 62210 | F6: =IFERROR(SUM('Data Sheet'!F18,'Data Sheet'!F20:F22, -1*'Data Sheet'!F19),0) -> 68490 | G6: =IFERROR(SUM('Data Sheet'!G18,'Data Sheet'!G20:G22, -1*'Data Sheet'!G19),0) -> 84819 | H6: =IFERROR(SUM('Data Sheet'!H18,'Data Sheet'!H20:H22, -1*'Data Sheet'!H19),0) -> 104880 | I6: =IFERROR(SUM('Data Sheet'!I18,'Data Sheet'!I20:I22, -1*'Data Sheet'!I19),0) -> 110030 | ... K6: =IFERROR(SUM('Data Sheet'!K18,'Data Sheet'!K20:K22, -1*'Data Sheet'!K19),0) -> 128257 | L6: =IFERROR(FORECASTING!D36,0) -> 137552.8 | M6: =IFERROR(FORECASTING!D37,0) -> 147622.02 | N6: =IFERROR(FORECASTING!D38,0) -> 157691.24 | O6: =IFERROR(FORECASTING!D39,0) -> 167760.45 | P6: =IFERROR(FORECASTING!D40,0) -> 177829.67
A8: GROSS MARGIN | B8: =IFERROR(B4-B6,0) -> 23875 | C8: =IFERROR(C4-C6,0) -> 24127 | D8: =IFERROR(D4-D6,0) -> 27229 | E8: =IFERROR(E4-E6,0) -> 28581 | F8: =IFERROR(F4-F6,0) -> 31982 | G8: =IFERROR(G4-G6,0) -> 36822 | H8: =IFERROR(H4-H6,0) -> 41887 | I8: =IFERROR(I4-I6,0) -> 43640 | ... P8: =IFERROR(P4-P6,0) -> 65515.309
A9: Other Income | B9: =IFERROR('Data Sheet'!B25,0) -> 3050 | C9: =IFERROR('Data Sheet'!C25,0) -> 3311 | D9: =IFERROR('Data Sheet'!D25,0) -> 2882 | E9: =IFERROR('Data Sheet'!E25,0) -> 2803 | F9: =IFERROR('Data Sheet'!F25,0) -> 2201 | G9: =IFERROR('Data Sheet'!G25,0) -> 2295 | H9: =IFERROR('Data Sheet'!H25,0) -> 2701 | I9: =IFERROR('Data Sheet'!I25,0) -> 4711 | ... K9: =IFERROR('Data Sheet'!K25,0) -> 3033 | L9: =IFERROR(FORECASTING!I36,0) -> 3418.8 | M9: =IFERROR(FORECASTING!I37,0) -> 3484.2727 | N9: =IFERROR(FORECASTING!I38,0) -> 3549.7455 | O9: =IFERROR(FORECASTING!I39,0) -> 3615.2182 | P9: =IFERROR(FORECASTING!I40,0) -> 3680.6909
A11: NET MARGIN | B11: =IFERROR(B8+B9,0) -> 26925 | C11: =IFERROR(C8+C9,0) -> 27438 | D11: =IFERROR(D8+D9,0) -> 30111 | E11: =IFERROR(E8+E9,0) -> 31384 | F11: =IFERROR(F8+F9,0) -> 34183 | G11: =IFERROR(G8+G9,0) -> 39117 | H11: =IFERROR(H8+H9,0) -> 44588 | I11: =IFERROR(I8+I9,0) -> 48351 | ... P11: =IFERROR(P8+P9,0) -> 69196
A12: SG&A | B12: =IFERROR(SUM('Data Sheet'!B23:B24),0) -> 5271 | C12: =IFERROR(SUM('Data Sheet'!C23:C24),0) -> 5305 | D12: =IFERROR(SUM('Data Sheet'!D23:D24),0) -> 7059 | E12: =IFERROR(SUM('Data Sheet'!E23:E24),0) -> 6314 | F12: =IFERROR(SUM('Data Sheet'!F23:F24),0) -> 4093 | G12: =IFERROR(SUM('Data Sheet'!G23:G24),0) -> 5331 | H12: =IFERROR(SUM('Data Sheet'!H23:H24),0) -> 6757 | I12: =IFERROR(SUM('Data Sheet'!I23:I24),0) -> 7215 | ... K12: =IFERROR(SUM('Data Sheet'!K23:K24),0) -> 8113 | L12: =IFERROR(FORECASTING!N36,0) -> 7661.8 | M12: =IFERROR(FORECASTING!N37,0) -> 7916.1818 | N12: =IFERROR(FORECASTING!N38,0) -> 8170.5636 | O12: =IFERROR(FORECASTING!N39,0) -> 8424.9455 | P12: =IFERROR(FORECASTING!N40,0) -> 8679.3273
A14: EBITDA | B14: =IFERROR(B11-B12,0) -> 21654 | C14: =IFERROR(C11-C12,0) -> 22133 | D14: =IFERROR(D11-D12,0) -> 23052 | E14: =IFERROR(E11-E12,0) -> 25070 | F14: =IFERROR(F11-F12,0) -> 30090 | G14: =IFERROR(G11-G12,0) -> 33786 | H14: =IFERROR(H11-H12,0) -> 37831 | I14: =IFERROR(I11-I12,0) -> 41136 | ... P14: =IFERROR(P11-P12,0) -> 60516.673
A15: Depreciation | B15: =IFERROR('Data Sheet'!B26,0) -> 1703 | C15: =IFERROR('Data Sheet'!C26,0) -> 1863 | D15: =IFERROR('Data Sheet'!D26,0) -> 2011 | E15: =IFERROR('Data Sheet'!E26,0) -> 2893 | F15: =IFERROR('Data Sheet'!F26,0) -> 3267 | G15: =IFERROR('Data Sheet'!G26,0) -> 3476 | H15: =IFERROR('Data Sheet'!H26,0) -> 4225 | I15: =IFERROR('Data Sheet'!I26,0) -> 4678 | ... K15: =IFERROR('Data Sheet'!K26,0) -> 4902 | L15: =IFERROR(FORECASTING!N56,0) -> 5615.4667 | M15: =FORECASTING!N57 -> 6021.3697 | N15: =FORECASTING!N58 -> 6427.2727 | O15: =FORECASTING!N59 -> 6833.1758 | P15: =FORECASTING!N60 -> 7239.0788
A16: Interest | B16: =IFERROR('Data Sheet'!B27,0) -> 0 | C16: =IFERROR('Data Sheet'!C27,0) -> 0 | D16: =IFERROR('Data Sheet'!D27,0) -> 0 | E16: =IFERROR('Data Sheet'!E27,0) -> 170 | F16: =IFERROR('Data Sheet'!F27,0) -> 195 | G16: =IFERROR('Data Sheet'!G27,0) -> 200 | H16: =IFERROR('Data Sheet'!H27,0) -> 284 | I16: =IFERROR('Data Sheet'!I27,0) -> 470 | ... K16: =IFERROR('Data Sheet'!K27,0) -> 416 | L16: =FORECASTING!D56 -> 526.86667 | M16: =IFERROR(FORECASTING!D57,0) -> 583.55152 | N16: =IFERROR(FORECASTING!D58,0) -> 640.23636 | O16: =IFERROR(FORECASTING!D59,0) -> 696.92121 | P16: =IFERROR(FORECASTING!D60,0) -> 753.60606
A18: Profit before tax | B18: =IFERROR('Data Sheet'!B28,0) -> 19951 | C18: =IFERROR('Data Sheet'!C28,0) -> 20270 | D18: =IFERROR('Data Sheet'!D28,0) -> 21041 | E18: =IFERROR('Data Sheet'!E28,0) -> 22007 | F18: =IFERROR('Data Sheet'!F28,0) -> 26628 | G18: =IFERROR('Data Sheet'!G28,0) -> 30110 | H18: =IFERROR('Data Sheet'!H28,0) -> 33322 | I18: =IFERROR('Data Sheet'!I28,0) -> 35988 | ... K18: =IFERROR('Data Sheet'!K28,0) -> 39995 | L18: =IFERROR(L14-L15-L16,0) -> 42489.467 | M18: =IFERROR(M14-M15-M16,0) -> 44998.097 | N18: =IFERROR(N14-N15-N16,0) -> 47506.727 | O18: =IFERROR(O14-O15-O16,0) -> 50015.358 | P18: =IFERROR(P14-P15-P16,0) -> 52523.988
A19: Tax | B19: =IFERROR('Data Sheet'!B29,0) -> 5598 | C19: =IFERROR('Data Sheet'!C29,0) -> 4241 | D19: =IFERROR('Data Sheet'!D29,0) -> 5631 | E19: =IFERROR('Data Sheet'!E29,0) -> 5368 | F19: =IFERROR('Data Sheet'!F29,0) -> 7205 | G19: =IFERROR('Data Sheet'!G29,0) -> 7964 | H19: =IFERROR('Data Sheet'!H29,0) -> 9214 | I19: =IFERROR('Data Sheet'!I29,0) -> 9740 | ... K19: =IFERROR('Data Sheet'!K29,0) -> 10521 | L19: =IFERROR(FORECASTING!I56,0) -> 11749.6 | M19: =IFERROR(FORECASTING!I57,0) -> 12497.891 | N19: =IFERROR(FORECASTING!I58,0) -> 13246.182 | O19: =IFERROR(FORECASTING!I59,0) -> 13994.473 | P19: =IFERROR(FORECASTING!I60,0) -> 14742.764
A21: Net profit | B21: =IFERROR(B18-B19,0) -> 14353 | C21: =IFERROR(C18-C19,0) -> 16029 | D21: =IFERROR(D18-D19,0) -> 15410 | E21: =IFERROR(E18-E19,0) -> 16639 | F21: =IFERROR(F18-F19,0) -> 19423 | G21: =IFERROR(G18-G19,0) -> 22146 | H21: =IFERROR(H18-H19,0) -> 24108 | I21: =IFERROR(I18-I19,0) -> 26248 | ... P21: =IFERROR(P18-P19,0) -> 37781.224
A23: NO. OF EQUITY SHARE | B23: =IFERROR('Data Sheet'!B93,0) -> 459.39 | C23: =IFERROR('Data Sheet'!C93,0) -> 436.82 | D23: =IFERROR('Data Sheet'!D93,0) -> 436.89 | E23: =IFERROR('Data Sheet'!E93,0) -> 425.9 | F23: =IFERROR('Data Sheet'!F93,0) -> 426.07 | G23: =IFERROR('Data Sheet'!G93,0) -> 420.67 | H23: =IFERROR('Data Sheet'!H93,0) -> 414.86 | I23: =IFERROR('Data Sheet'!I93,0) -> 415.09 | ... K23: =IFERROR('Data Sheet'!K93,0) -> 405.56 | L23: =IFERROR(L21/L25,0) -> 406.67057 | M23: =IFERROR(M21/M25,0) -> 404.9314 | N23: =IFERROR(N21/N25,0) -> 403.38358 | O23: =IFERROR(O21/O25,0) -> 401.99715 | P23: =IFERROR(P21/P25,0) -> 400.74813
A25: EPS | B25: =IFERROR(B21/B23,0) -> 31.243606 | C25: =IFERROR(C21/C23,0) -> 36.694748 | D25: =IFERROR(D21/D23,0) -> 35.272036 | E25: =IFERROR(E21/E23,0) -> 39.067856 | F25: =IFERROR(F21/F23,0) -> 45.586406 | G25: =IFERROR(G21/G23,0) -> 52.644591 | H25: =IFERROR(H21/H23,0) -> 58.11117 | I25: =IFERROR(I21/I23,0) -> 63.234479 | ... K25: =IFERROR(K21/K23,0) -> 72.67482 | L25: =IFERROR(FORECASTING!N15,0) -> 75.589111 | M25: =IFERROR(FORECASTING!N16,0) -> 80.261016 | N25: =IFERROR(FORECASTING!N17,0) -> 84.932921 | O25: =IFERROR(FORECASTING!N18,0) -> 89.604826 | P25: =IFERROR(FORECASTING!N19,0) -> 94.276732
A27: EPS GROWTH% | C27: =IFERROR(C25/B25-1,0) -> 0.17447227 | D27: =IFERROR(D25/C25-1,0) -> -0.038771542 | E27: =IFERROR(E25/D25-1,0) -> 0.10761556 | F27: =IFERROR(F25/E25-1,0) -> 0.16685199 | G27: =IFERROR(G25/F25-1,0) -> 0.15483091 | H27: =IFERROR(H25/G25-1,0) -> 0.10383933 | I27: =IFERROR(I25/H25-1,0) -> 0.088163932 | J27: =IFERROR(J25/I25-1,0) -> 0.018536361 | ... P27: =IFERROR(P25/O25-1,0) -> 0.05213899
A28: Price to earning | B28: =IF(B29>0,B29/B25,"") -> 16.359507 | C28: =IF(C29>0,C29/C25,"") -> 15.421825 | D28: =IF(D29>0,D29/D25,"") -> 21.088944 | E28: =IF(E29>0,E29/E25,"") -> 16.420148 | F28: =IF(F29>0,F29/F25,"") -> 30.010043 | G28: =IF(G29>0,G29/G25,"") -> 36.221195 | H28: =IF(H29>0,H29/H25,"") -> 24.572728 | I28: =IF(I29>0,I29/I25,"") -> 23.690398 | ... P28: =IF(P29>0,P29/P25,"") -> 24.614334
A29: Price | B29: =IFERROR('Data Sheet'!B90,0) -> 511.13 | C29: =IFERROR('Data Sheet'!C90,0) -> 565.9 | D29: =IFERROR('Data Sheet'!D90,0) -> 743.85 | E29: =IFERROR('Data Sheet'!E90,0) -> 641.5 | F29: =IFERROR('Data Sheet'!F90,0) -> 1368.05 | G29: =IFERROR('Data Sheet'!G90,0) -> 1906.85 | H29: =IFERROR('Data Sheet'!H90,0) -> 1427.95 | I29: =IFERROR('Data Sheet'!I90,0) -> 1498.05 | ... K29: =IFERROR('Data Sheet'!K90,0) -> 1250.6 | L29: =IFERROR(FORECASTING!D76,0) -> 1827.0407 | M29: =IFERROR(FORECASTING!D77,0) -> 1950.4202 | N29: =IFERROR(FORECASTING!D78,0) -> 2073.7998 | O29: =IFERROR(FORECASTING!D79,0) -> 2197.1794 | P29: =IFERROR(FORECASTING!D80,0) -> 2320.559
A31: RATIOS:
A32: DIVIDEND PER SHARE | B32: =IFERROR('Data Sheet'!B31/'Profit & Loss'!B23,0) -> 12.824833 | C32: =IFERROR('Data Sheet'!C31/'Profit & Loss'!C23,0) -> 21.669337 | D32: =IFERROR('Data Sheet'!D31/'Profit & Loss'!D23,0) -> 21.109433 | E32: =IFERROR('Data Sheet'!E31/'Profit & Loss'!E23,0) -> 17.438366 | F32: =IFERROR('Data Sheet'!F31/'Profit & Loss'!F23,0) -> 26.91952 | G32: =IFERROR('Data Sheet'!G31/'Profit & Loss'!G23,0) -> 30.92115 | H32: =IFERROR('Data Sheet'!H31/'Profit & Loss'!H23,0) -> 33.913127 | I32: =IFERROR('Data Sheet'!I31/'Profit & Loss'!I23,0) -> 45.901371 | ... K32: =IFERROR('Data Sheet'!K31/'Profit & Loss'!K23,0) -> 47.91005 | L32: =IFERROR(L37/L23,0) -> 51.769684 | M32: =IFERROR(M37/M23,0) -> 55.748788 | N32: =IFERROR(N37/N23,0) -> 59.733874 | O32: =IFERROR(O37/O23,0) -> 63.724064 | P32: =IFERROR(P37/P23,0) -> 67.718645
A33: OPM | B33: =IF(B8>0,B8/B4,0) -> 0.34862158 | C33: =IF(C8>0,C8/C4,0) -> 0.34212019 | D33: =IF(D8>0,D8/D4,0) -> 0.32934986 | E33: =IF(E8>0,E8/E4,0) -> 0.31479993 | F33: =IF(F8>0,F8/F4,0) -> 0.31831754 | G33: =IF(G8>0,G8/G4,0) -> 0.30271043 | H33: =IF(H8>0,H8/H4,0) -> 0.28539794 | I33: =IF(I8>0,I8/I4,0) -> 0.28398516 | ... P33: =IF(P8>0,P8/P4,0) -> 0.26922811
A34: DIVIDEND PAYOUT RATIO | B34: =IFERROR(B32/B25,0) -> 0.41047865 | C34: =IFERROR(C32/C25,0) -> 0.59052966 | D34: =IFERROR(D32/D25,0) -> 0.59847502 | E34: =IFERROR(E32/E25,0) -> 0.44636096 | F34: =IFERROR(F32/F25,0) -> 0.5905164 | G34: =IFERROR(G32/G25,0) -> 0.58735663 | H34: =IFERROR(H32/H25,0) -> 0.58359051 | I34: =IFERROR(I32/I25,0) -> 0.7258915 | ... P34: =IFERROR(P32/P25,0) -> 0.71829649
A35: RETAINED EARNINGS | B35: =IFERROR(1-B34,0) -> 0.58952135 | C35: =IFERROR(1-C34,0) -> 0.40947034 | D35: =IFERROR(1-D34,0) -> 0.40152498 | E35: =IFERROR(1-E34,0) -> 0.55363904 | F35: =IFERROR(1-F34,0) -> 0.4094836 | G35: =IFERROR(1-G34,0) -> 0.41264337 | H35: =IFERROR(1-H34,0) -> 0.41640949 | I35: =IFERROR(1-I34,0) -> 0.2741085 | ... P35: =IFERROR(1-P34,0) -> 0.28170351
A37: DIVIDEND AMOUNT | B37: =IFERROR('Data Sheet'!B31,0) -> 5891.6 | C37: =IFERROR('Data Sheet'!C31,0) -> 9465.6 | D37: =IFERROR('Data Sheet'!D31,0) -> 9222.5 | E37: =IFERROR('Data Sheet'!E31,0) -> 7427 | F37: =IFERROR('Data Sheet'!F31,0) -> 11469.6 | G37: =IFERROR('Data Sheet'!G31,0) -> 13007.6 | H37: =IFERROR('Data Sheet'!H31,0) -> 14069.2 | I37: =IFERROR('Data Sheet'!I31,0) -> 19053.2 | ... K37: =IFERROR('Data Sheet'!K31,0) -> 19430.4 | L37: =IFERROR(FORECASTING!I76,0) -> 21053.207 | M37: =IFERROR(FORECASTING!I77,0) -> 22574.435 | N37: =IFERROR(FORECASTING!I78,0) -> 24095.664 | O37: =IFERROR(FORECASTING!I79,0) -> 25616.892 | P37: =IFERROR(FORECASTING!I80,0) -> 27138.121
A58: EXPENSES % REVENUE | B58: =IFERROR(B6/B4,0) -> 0.65137842 | C58: =IFERROR(C6/C4,0) -> 0.65787981 | D58: =IFERROR(D6/D4,0) -> 0.67065014 | E58: =IFERROR(E6/E4,0) -> 0.68520007 | F58: =IFERROR(F6/F4,0) -> 0.68168246 | G58: =IFERROR(G6/G4,0) -> 0.69728957 | H58: =IFERROR(H6/H4,0) -> 0.71460206 | I58: =IFERROR(I6/I4,0) -> 0.71601484 | ... P58: =IFERROR(P6/P4,0) -> 0.73077189
A59: EBITDA MARGIN | B59: =IFERROR(B14/B4,0) -> 0.31619064 | C59: =IFERROR(C14/C4,0) -> 0.31384532 | D59: =IFERROR(D14/D4,0) -> 0.27882673 | E59: =IFERROR(E14/E4,0) -> 0.27612869 | F59: =IFERROR(F14/F4,0) -> 0.29948642 | G59: =IFERROR(G14/G4,0) -> 0.27775174 | H59: =IFERROR(H14/H4,0) -> 0.2577623 | I59: =IFERROR(I14/I4,0) -> 0.26769051 | ... P59: =IFERROR(P14/P4,0) -> 0.24868675
A60: GROSS MARGIN % | B60: =IFERROR(B11/B4,0) -> 0.39315753 | C60: =IFERROR(C11/C4,0) -> 0.38907008 | D60: =IFERROR(D11/D4,0) -> 0.36420925 | E60: =IFERROR(E11/E4,0) -> 0.34567303 | F60: =IFERROR(F11/F4,0) -> 0.34022414 | G60: =IFERROR(G11/G4,0) -> 0.32157743 | H60: =IFERROR(H11/H4,0) -> 0.30380126 | I60: =IFERROR(I11/I4,0) -> 0.31464176 | ... P60: =IFERROR(P11/P4,0) -> 0.28435351
A61: SG&A % | B61: =IFERROR(B12/B4,0) -> 0.076966883 | C61: =IFERROR(C12/C4,0) -> 0.075224753 | D61: =IFERROR(D12/D4,0) -> 0.085382522 | E61: =IFERROR(E12/E4,0) -> 0.069544338 | F61: =IFERROR(F12/F4,0) -> 0.040737718 | G61: =IFERROR(G12/G4,0) -> 0.043825684 | H61: =IFERROR(H12/H4,0) -> 0.04603896 | I61: =IFERROR(I12/I4,0) -> 0.046951259 | ... P61: =IFERROR(P12/P4,0) -> 0.035666761
A62: PROBIT BEFORE TAX % | B62: =IFERROR(B18/B4,0) -> 0.29132352 | C62: =IFERROR(C18/C4,0) -> 0.28742804 | D62: =IFERROR(D18/D4,0) -> 0.25450257 | E62: =IFERROR(E18/E4,0) -> 0.24239187 | F62: =IFERROR(F18/F4,0) -> 0.26502906 | G62: =IFERROR(G18/G4,0) -> 0.24753167 | H62: =IFERROR(H18/H4,0) -> 0.22704014 | I62: =IFERROR(I18/I4,0) -> 0.23419015 | ... P62: =IFERROR(P18/P4,0) -> 0.21584167
A63: NET PROFIT% | B63: =IFERROR(B21/B4,0) -> 0.2095818 | C63: =IFERROR(C21/C4,0) -> 0.22729077 | D63: =IFERROR(D21/D4,0) -> 0.1863925 | E63: =IFERROR(E21/E4,0) -> 0.18326706 | F63: =IFERROR(F21/F4,0) -> 0.19331754 | G63: =IFERROR(G21/G4,0) -> 0.18206033 | H63: =IFERROR(H21/H4,0) -> 0.16426036 | I63: =IFERROR(I21/I4,0) -> 0.17080757 | ... P63: =IFERROR(P21/P4,0) -> 0.15525787

Sheet Balance Sheet
A1: ='Profit & Loss'!A1 -> INFOSYS LTD | E1: =UPDATE | J1: SCREENER.IN
A3: Narration | B3: ='Data Sheet'!B56 -> 42825 | C3: ='Data Sheet'!C56 -> 43190 | D3: ='Data Sheet'!D56 -> 43555 | E3: ='Data Sheet'!E56 -> 43921 | F3: ='Data Sheet'!F56 -> 44286 | G3: ='Data Sheet'!G56 -> 44651 | H3: ='Data Sheet'!H56 -> 45016 | I3: ='Data Sheet'!I56 -> 45382 | ... K3: ='Data Sheet'!K56 -> 46112 | L3: 46473 | M3: 46840 | N3: 47206 | O3: 47572 | P3: 47938
A4: Equity Share Capital | B4: =IFERROR('Data Sheet'!B57,0) -> 1144 | C4: =IFERROR('Data Sheet'!C57,0) -> 1088 | D4: =IFERROR('Data Sheet'!D57,0) -> 2170 | E4: =IFERROR('Data Sheet'!E57,0) -> 2122 | F4: =IFERROR('Data Sheet'!F57,0) -> 2124 | G4: =IFERROR('Data Sheet'!G57,0) -> 2098 | H4: =IFERROR('Data Sheet'!H57,0) -> 2069 | I4: =IFERROR('Data Sheet'!I57,0) -> 2071 | ... K4: =IFERROR('Data Sheet'!K57,0) -> 2024 | L4: =IFERROR(FORECASTING!N76,0) -> 2369.4667 | M4: =IFERROR(FORECASTING!N77,0) -> 2455.1333 | N4: =IFERROR(FORECASTING!N78,0) -> 2540.8 | O4: =IFERROR(FORECASTING!N79,0) -> 2626.4667 | P4: =IFERROR(FORECASTING!N80,0) -> 2712.1333
A5: Reserves | B5: =IFERROR('Data Sheet'!B58,0) -> 67838 | C5: =IFERROR('Data Sheet'!C58,0) -> 63835 | D5: =IFERROR('Data Sheet'!D58,0) -> 62778 | E5: =IFERROR('Data Sheet'!E58,0) -> 63328 | F5: =IFERROR('Data Sheet'!F58,0) -> 74227 | G5: =IFERROR('Data Sheet'!G58,0) -> 73252 | H5: =IFERROR('Data Sheet'!H58,0) -> 73338 | I5: =IFERROR('Data Sheet'!I58,0) -> 86045 | ... K5: =IFERROR('Data Sheet'!K58,0) -> 90828 | L5: =IFERROR(FORECASTING!D96,0) -> 93643.733 | M5: =IFERROR(FORECASTING!D97,0) -> 97047.794 | N5: =IFERROR(FORECASTING!D98,0) -> 100451.85 | O5: =IFERROR(FORECASTING!D99,0) -> 103855.92 | P5: =IFERROR(FORECASTING!D100,0) -> 107259.98
A6: Borrowings | B6: =IFERROR('Data Sheet'!B59,0) -> 0 | C6: =IFERROR('Data Sheet'!C59,0) -> 0 | D6: =IFERROR('Data Sheet'!D59,0) -> 0 | E6: =IFERROR('Data Sheet'!E59,0) -> 4633 | F6: =IFERROR('Data Sheet'!F59,0) -> 5325 | G6: =IFERROR('Data Sheet'!G59,0) -> 5474 | H6: =IFERROR('Data Sheet'!H59,0) -> 8299 | I6: =IFERROR('Data Sheet'!I59,0) -> 8359 | ... K6: =IFERROR('Data Sheet'!K59,0) -> 9176 | L6: =IFERROR(FORECASTING!I96,0) -> 11386.467 | M6: =IFERROR(FORECASTING!I97,0) -> 12556.861 | N6: =IFERROR(FORECASTING!I98,0) -> 13727.255 | O6: =IFERROR(FORECASTING!I99,0) -> 14897.648 | P6: =IFERROR(FORECASTING!I100,0) -> 16068.042
A7: Other Liabilities | B7: =IFERROR('Data Sheet'!B60,0) -> 14166 | C7: =IFERROR('Data Sheet'!C60,0) -> 14426 | D7: =IFERROR('Data Sheet'!D60,0) -> 19118 | E7: =IFERROR('Data Sheet'!E60,0) -> 21717 | F7: =IFERROR('Data Sheet'!F60,0) -> 25835 | G7: =IFERROR('Data Sheet'!G60,0) -> 35905 | H7: =IFERROR('Data Sheet'!H60,0) -> 40890 | I7: =IFERROR('Data Sheet'!I60,0) -> 39545 | ... K7: =IFERROR('Data Sheet'!K60,0) -> 52260 | L7: =IFERROR(FORECASTING!$N96,0) -> 54689.133 | M7: =IFERROR(FORECASTING!N97,0) -> 59039.667 | N7: =IFERROR(FORECASTING!N98,0) -> 63390.2 | O7: =IFERROR(FORECASTING!N99,0) -> 67740.733 | P7: =IFERROR(FORECASTING!$N100,0) -> 72091.267
A8: TOTAL LIABILITIES | B8: =IFERROR('Data Sheet'!B61,0) -> 83148 | C8: =IFERROR('Data Sheet'!C61,0) -> 79349 | D8: =IFERROR('Data Sheet'!D61,0) -> 84066 | E8: =IFERROR('Data Sheet'!E61,0) -> 91800 | F8: =IFERROR('Data Sheet'!F61,0) -> 107511 | G8: =IFERROR('Data Sheet'!G61,0) -> 116729 | H8: =IFERROR('Data Sheet'!H61,0) -> 124596 | I8: =IFERROR('Data Sheet'!I61,0) -> 136020 | ... K8: =IFERROR('Data Sheet'!K61,0) -> 154288 | L8: =IFERROR(SUM(L4:L7),0) -> 162088.8 | M8: =IFERROR(SUM(M4:M7),0) -> 171099.45 | N8: =IFERROR(SUM(N4:N7),0) -> 180110.11 | O8: =IFERROR(SUM(O4:O7),0) -> 189120.76 | P8: =IFERROR(SUM(P4:P7),0) -> 198131.42
A10: FIXED ASSESTS NET BLOCK | B10: =IFERROR('Data Sheet'!B62,0) -> 14179 | C10: =IFERROR('Data Sheet'!C62,0) -> 12574 | D10: =IFERROR('Data Sheet'!D62,0) -> 15710 | E10: =IFERROR('Data Sheet'!E62,0) -> 23789 | F10: =IFERROR('Data Sheet'!F62,0) -> 25505 | G10: =IFERROR('Data Sheet'!G62,0) -> 25800 | H10: =IFERROR('Data Sheet'!H62,0) -> 29225 | I10: =IFERROR('Data Sheet'!I62,0) -> 27622 | ... K10: =IFERROR('Data Sheet'!K62,0) -> 33770 | L10: =IFERROR(FORECASTING!D116,0) -> 36619.867 | M10: =IFERROR(FORECASTING!D117,0) -> 38930.115 | N10: =IFERROR(FORECASTING!D118,0) -> 41240.364 | O10: =IFERROR(FORECASTING!D119,0) -> 43550.612 | P10: =IFERROR(FORECASTING!D120,0) -> 45860.861
A11: Capital Work in Progress | B11: =IFERROR('Data Sheet'!B63,0) -> 1365 | C11: =IFERROR('Data Sheet'!C63,0) -> 1606 | D11: =IFERROR('Data Sheet'!D63,0) -> 1388 | E11: =IFERROR('Data Sheet'!E63,0) -> 954 | F11: =IFERROR('Data Sheet'!F63,0) -> 922 | G11: =IFERROR('Data Sheet'!G63,0) -> 416 | H11: =IFERROR('Data Sheet'!H63,0) -> 288 | I11: =IFERROR('Data Sheet'!I63,0) -> 293 | ... K11: =IFERROR('Data Sheet'!K63,0) -> 526
A12: Investments | B12: =IFERROR('Data Sheet'!B64,0) -> 16423 | C12: =IFERROR('Data Sheet'!C64,0) -> 12163 | D12: =IFERROR('Data Sheet'!D64,0) -> 11261 | E12: =IFERROR('Data Sheet'!E64,0) -> 8792 | F12: =IFERROR('Data Sheet'!F64,0) -> 14205 | G12: =IFERROR('Data Sheet'!G64,0) -> 20324 | H12: =IFERROR('Data Sheet'!H64,0) -> 19478 | I12: =IFERROR('Data Sheet'!I64,0) -> 24623 | ... K12: =IFERROR('Data Sheet'!K64,0) -> 21880 | L12: =IFERROR(FORECASTING!I116,0) -> 25060.533 | M12: =IFERROR(FORECASTING!I117,0) -> 26477.176 | N12: =IFERROR(FORECASTING!I118,0) -> 27893.818 | O12: =IFERROR(FORECASTING!I119,0) -> 29310.461 | P12: =IFERROR(FORECASTING!I120,0) -> 30727.103
A13: Other Assets | B13: =IFERROR('Data Sheet'!B65-SUM('Data Sheet'!B67:B69),0) -> 16234 | C13: =IFERROR('Data Sheet'!C65-SUM('Data Sheet'!C67:C69),0) -> 20046 | D13: =IFERROR('Data Sheet'!D65-SUM('Data Sheet'!D67:D69),0) -> 21312 | E13: =IFERROR('Data Sheet'!E65-SUM('Data Sheet'!E67:E69),0) -> 21129 | F13: =IFERROR('Data Sheet'!F65-SUM('Data Sheet'!F67:F69),0) -> 22871 | G13: =IFERROR('Data Sheet'!G65-SUM('Data Sheet'!G67:G69),0) -> 30019 | H13: =IFERROR('Data Sheet'!H65-SUM('Data Sheet'!H67:H69),0) -> 38008 | I13: =IFERROR('Data Sheet'!I65-SUM('Data Sheet'!I67:I69),0) -> 38503 | ... K13: =IFERROR('Data Sheet'!K65-SUM('Data Sheet'!K67:K69),0) -> 40677 | L13: =IFERROR(FORECASTING!N116,0) -> 44615.4 | M13: =IFERROR(FORECASTING!N117,0) -> 47533.382 | N13: =IFERROR(FORECASTING!N118,0) -> 50451.364 | O13: =IFERROR(FORECASTING!N119,0) -> 53369.345 | P13: =IFERROR(FORECASTING!N120,0) -> 56287.327
A14: TOTAL NON CURRENT ASSESTS | B14: =IFERROR(SUM(B10:B13),0) -> 48201 | C14: =IFERROR(SUM(C10:C13),0) -> 46389 | D14: =IFERROR(SUM(D10:D13),0) -> 49671 | E14: =IFERROR(SUM(E10:E13),0) -> 54664 | F14: =IFERROR(SUM(F10:F13),0) -> 63503 | G14: =IFERROR(SUM(G10:G13),0) -> 76559 | H14: =IFERROR(SUM(H10:H13),0) -> 86999 | I14: =IFERROR(SUM(I10:I13),0) -> 91041 | ... P14: =IFERROR(SUM(P10:P13),0) -> 132875.29
A16: Receivables | B16: =IFERROR('Data Sheet'!B67,0) -> 12322 | C16: =IFERROR('Data Sheet'!C67,0) -> 13142 | D16: =IFERROR('Data Sheet'!D67,0) -> 14827 | E16: =IFERROR('Data Sheet'!E67,0) -> 18487 | F16: =IFERROR('Data Sheet'!F67,0) -> 19294 | G16: =IFERROR('Data Sheet'!G67,0) -> 22698 | H16: =IFERROR('Data Sheet'!H67,0) -> 25424 | I16: =IFERROR('Data Sheet'!I67,0) -> 30193 | ... K16: =IFERROR('Data Sheet'!K67,0) -> 35234 | L16: 0 | M16: 0 | N16: 0 | O16: 0 | P16: 0
A17: Inventory | B17: =IFERROR('Data Sheet'!B68,0) -> 0 | C17: =IFERROR('Data Sheet'!C68,0) -> 0 | D17: =IFERROR('Data Sheet'!D68,0) -> 0 | E17: =IFERROR('Data Sheet'!E68,0) -> 0 | F17: =IFERROR('Data Sheet'!F68,0) -> 0 | G17: =IFERROR('Data Sheet'!G68,0) -> 0 | H17: =IFERROR('Data Sheet'!H68,0) -> 0 | I17: =IFERROR('Data Sheet'!I68,0) -> 0 | ... K17: =IFERROR('Data Sheet'!K68,0) -> 0 | L17: 0 | M17: 0 | N17: 0 | O17: 0 | P17: 0
A18: Cash & Bank | B18: =IFERROR('Data Sheet'!B69,0) -> 22625 | C18: =IFERROR('Data Sheet'!C69,0) -> 19818 | D18: =IFERROR('Data Sheet'!D69,0) -> 19568 | E18: =IFERROR('Data Sheet'!E69,0) -> 18649 | F18: =IFERROR('Data Sheet'!F69,0) -> 24714 | G18: =IFERROR('Data Sheet'!G69,0) -> 17472 | H18: =IFERROR('Data Sheet'!H69,0) -> 12173 | I18: =IFERROR('Data Sheet'!I69,0) -> 14786 | ... K18: =IFERROR('Data Sheet'!K69,0) -> 22201 | L18: =IFERROR(FORECASTING!D136,0) -> 18914.867 | M18: =IFERROR(FORECASTING!D137,0) -> 18781.915 | N18: =IFERROR(FORECASTING!D138,0) -> 18648.964 | O18: =IFERROR(FORECASTING!D139,0) -> 18516.012 | P18: =IFERROR(FORECASTING!D140,0) -> 18383.061
A19: TOTAL CURRENT ASSESTS | B19: =IFERROR(SUM(B16:B18),0) -> 34947 | C19: =IFERROR(SUM(C16:C18),0) -> 32960 | D19: =IFERROR(SUM(D16:D18),0) -> 34395 | E19: =IFERROR(SUM(E16:E18),0) -> 37136 | F19: =IFERROR(SUM(F16:F18),0) -> 44008 | G19: =IFERROR(SUM(G16:G18),0) -> 40170 | H19: =IFERROR(SUM(H16:H18),0) -> 37597 | I19: =IFERROR(SUM(I16:I18),0) -> 44979 | ... P19: =IFERROR(SUM(P16:P18),0) -> 18383.061
A22: TOTAL ASSESTS | B22: =IFERROR(B14+B19,0) -> 83148 | C22: =IFERROR(C14+C19,0) -> 79349 | D22: =IFERROR(D14+D19,0) -> 84066 | E22: =IFERROR(E14+E19,0) -> 91800 | F22: =IFERROR(F14+F19,0) -> 107511 | G22: =IFERROR(G14+G19,0) -> 116729 | H22: =IFERROR(H14+H19,0) -> 124596 | I22: =IFERROR(I14+I19,0) -> 136020 | ... P22: =IFERROR(P14+P19,0) -> 151258.35
A24: CHECK | B24: =B22=B8 -> TRUE | C24: =C22=C8 -> TRUE | D24: =D22=D8 -> TRUE | E24: =E22=E8 -> TRUE | F24: =F22=F8 -> TRUE | G24: =G22=G8 -> TRUE | H24: =H22=H8 -> TRUE | I24: =I22=I8 -> TRUE | ... P24: =P22=P8 -> FALSE

Sheet Cash Flow
A1: ='Balance Sheet'!A1 -> INFOSYS LTD | E1: =UPDATE | J1: SCREENER.IN
A3: Narration | B3: ='Data Sheet'!B81 -> 42825 | C3: ='Data Sheet'!C81 -> 43190 | D3: ='Data Sheet'!D81 -> 43555 | E3: ='Data Sheet'!E81 -> 43921 | F3: ='Data Sheet'!F81 -> 44286 | G3: ='Data Sheet'!G81 -> 44651 | H3: ='Data Sheet'!H81 -> 45016 | I3: ='Data Sheet'!I81 -> 45382 | ... K3: ='Data Sheet'!K81 -> 46112 | L3: 46473 | M3: 46840 | N3: 47206 | O3: 47572 | P3: 47938
A5: CASH FROM OPERATING ACTIVITIES | B5: =IFERROR('Data Sheet'!B82,0) -> 11531 | C5: =IFERROR('Data Sheet'!C82,0) -> 13218 | D5: =IFERROR('Data Sheet'!D82,0) -> 14841 | E5: =IFERROR('Data Sheet'!E82,0) -> 17003 | F5: =IFERROR('Data Sheet'!F82,0) -> 23224 | G5: =IFERROR('Data Sheet'!G82,0) -> 23885 | H5: =IFERROR('Data Sheet'!H82,0) -> 22467 | I5: =IFERROR('Data Sheet'!I82,0) -> 25210 | ... K5: =IFERROR('Data Sheet'!K82,0) -> 33986 | L5: =IFERROR(FORECASTING!I136,0) -> 36383.4 | M5: =IFERROR(FORECASTING!I137,0) -> 38979.309 | N5: =IFERROR(FORECASTING!I138,0) -> 41575.218 | O5: =IFERROR(FORECASTING!I139,0) -> 44171.127 | P5: =IFERROR(FORECASTING!I140,0) -> 46767.036
A7: CASH FLOW FROM INVESTING ACTIVITIES | B7: =IFERROR('Data Sheet'!B83,0) -> -14664 | C7: =IFERROR('Data Sheet'!C83,0) -> 4533 | D7: =IFERROR('Data Sheet'!D83,0) -> -632 | E7: =IFERROR('Data Sheet'!E83,0) -> -331 | F7: =IFERROR('Data Sheet'!F83,0) -> -7373 | G7: =IFERROR('Data Sheet'!G83,0) -> -6485 | H7: =IFERROR('Data Sheet'!H83,0) -> -1071 | I7: =IFERROR('Data Sheet'!I83,0) -> -5093 | ... K7: =IFERROR('Data Sheet'!K83,0) -> 3546 | L7: {=TRANSPOSE(FORECASTING!N136:N140)} -> 239.06667 | M7: 817.69697 | N7: 1396.3273 | O7: 1974.9576 | P7: 2553.5879
A9: CASH FLOW FROM FINANCING ACTIVITIES | B9: =IFERROR('Data Sheet'!B84,0) -> -6939 | C9: =IFERROR('Data Sheet'!C84,0) -> -20505 | D9: =IFERROR('Data Sheet'!D84,0) -> -14512 | E9: =IFERROR('Data Sheet'!E84,0) -> -17591 | F9: =IFERROR('Data Sheet'!F84,0) -> -9786 | G9: =IFERROR('Data Sheet'!G84,0) -> -24642 | H9: =IFERROR('Data Sheet'!H84,0) -> -26695 | I9: =IFERROR('Data Sheet'!I84,0) -> -17504 | ... K9: =IFERROR('Data Sheet'!K84,0) -> -39786 | L9: {=TRANSPOSE(FORECASTING!D156:D160)} -> -32823.533 | M9: -35116.521 | N9: -37409.509 | O9: -39702.497 | P9: -41995.485
A13: NET CASH FLOW | B13: =IFERROR(SUM(B5:B9),0) -> -10072 | C13: =IFERROR(SUM(C5:C9),0) -> -2754 | D13: =IFERROR(SUM(D5:D9),0) -> -303 | E13: =IFERROR(SUM(E5:E9),0) -> -919 | F13: =IFERROR(SUM(F5:F9),0) -> 6065 | G13: =IFERROR(SUM(G5:G9),0) -> -7242 | H13: =IFERROR(SUM(H5:H9),0) -> -5299 | I13: =IFERROR(SUM(I5:I9),0) -> 2613 | ... P13: =IFERROR(SUM(P5:P9),0) -> 7325.1394
H28: =IFERROR(SUM(#REF!),0) -> 0 | I28: =IFERROR(SUM(#REF!),0) -> 0 | J28: =IFERROR(SUM(#REF!),0) -> 0 | K28: =IFERROR(SUM(#REF!),0) -> 0

Sheet RATIO ANALYSIS
G1: RATIO ANALYSIS | T1: LAST 10 HISTORICAL YEARS
C3: 42825 | D3: 43190 | E3: 43555 | F3: 43921 | G3: 44286 | H3: 44651 | I3: 45016 | J3: 45382 | K3: 45747 | L3: 46112 | M3: 46473 | N3: 46840 | O3: 47206 | P3: 47572 | Q3: 47938 | T3: TREND | U3: MEAN | V3: MEDIAN
B4: SALES GROWTH | C4: - | D4: =IFERROR(Annual[[#This Row],[Column3]]/Annual[[#This Row],[Column2]]-1,0) -> 0.029758776 | E4: =IFERROR(Annual[[#This Row],[Column4]]/Annual[[#This Row],[Column3]]-1,0) -> 0.1723292 | F4: =IFERROR(Annual[[#This Row],[Column5]]/Annual[[#This Row],[Column4]]-1,0) -> 0.098167523 | G4: =IFERROR(Annual[[#This Row],[Column6]]/Annual[[#This Row],[Column5]]-1,0) -> 0.10662951 | H4: =IFERROR(Annual[[#This Row],[Column7]]/Annual[[#This Row],[Column6]]-1,0) -> 0.21069552 | I4: =IFERROR(Annual[[#This Row],[Column8]]/Annual[[#This Row],[Column7]]-1,0) -> 0.20655864 | J4: =IFERROR(Annual[[#This Row],[Column9]]/Annual[[#This Row],[Column8]]-1,0) -> 0.047033734 | K4: =IFERROR(Annual[[#This Row],[Column10]]/Annual[[#This Row],[Column9]]-1,0) -> 0.060649444 | L4: =IFERROR(Annual[[#This Row],[Column11]]/Annual[[#This Row],[Column10]]-1,0) -> 0.096079514 | M4: =IFERROR(Annual[[#This Row],[Column12]]/Annual[[#This Row],[Column11]]-1,0) -> 0.065925553 | N4: =IFERROR(Annual[[#This Row],[Column13]]/Annual[[#This Row],[Column12]]-1,0) -> 0.069471786 | O4: =IFERROR(Annual[[#This Row],[Column14]]/Annual[[#This Row],[Column13]]-1,0) -> 0.06495897 | P4: =IFERROR(Annual[[#This Row],[Column15]]/Annual[[#This Row],[Column14]]-1,0) -> 0.060996688 | Q4: =IFERROR(Annual[[#This Row],[Column16]]/Annual[[#This Row],[Column15]]-1,0) -> 0.057489989 | U4: =IFERROR(AVERAGE(D4:L4),0) -> 0.11421132 | V4: =IFERROR(MEDIAN(C4:L4),0) -> 0.098167523
B5: EBITDA GROWTH | C5: - | D5: =IFERROR('Profit & Loss'!C14/'Profit & Loss'!B14-1,0) -> 0.022120624 | E5: =IFERROR('Profit & Loss'!D14/'Profit & Loss'!C14-1,0) -> 0.04152171 | F5: =IFERROR('Profit & Loss'!E14/'Profit & Loss'!D14-1,0) -> 0.087541211 | G5: =IFERROR('Profit & Loss'!F14/'Profit & Loss'!E14-1,0) -> 0.20023933 | H5: =IFERROR('Profit & Loss'!G14/'Profit & Loss'!F14-1,0) -> 0.12283151 | I5: =IFERROR('Profit & Loss'!H14/'Profit & Loss'!G14-1,0) -> 0.11972415 | J5: =IFERROR('Profit & Loss'!I14/'Profit & Loss'!H14-1,0) -> 0.087362216 | K5: =IFERROR('Profit & Loss'!J14/'Profit & Loss'!I14-1,0) -> 0.041326332 | ... Q5: =IFERROR('Profit & Loss'!P14/'Profit & Loss'!O14-1,0) -> 0.051632543 | U5: =IFERROR(AVERAGE(D5:L5),0) -> 0.086721363 | V5: =IFERROR(MEDIAN(C5:L5),0) -> 0.087362216
B6: EBT GROWTH | C6: - | D6: =IFERROR('Profit & Loss'!C18/'Profit & Loss'!B18-1,0) -> 0.015989173 | E6: =IFERROR('Profit & Loss'!D18/'Profit & Loss'!C18-1,0) -> 0.038036507 | F6: =IFERROR('Profit & Loss'!E18/'Profit & Loss'!D18-1,0) -> 0.045910365 | G6: =IFERROR('Profit & Loss'!F18/'Profit & Loss'!E18-1,0) -> 0.20997864 | H6: =IFERROR('Profit & Loss'!G18/'Profit & Loss'!F18-1,0) -> 0.13076461 | I6: =IFERROR('Profit & Loss'!H18/'Profit & Loss'!G18-1,0) -> 0.10667552 | J6: =IFERROR('Profit & Loss'!I18/'Profit & Loss'!H18-1,0) -> 0.080007202 | K6: =IFERROR('Profit & Loss'!J18/'Profit & Loss'!I18-1,0) -> 0.045015005 | ... Q6: =IFERROR('Profit & Loss'!P18/'Profit & Loss'!O18-1,0) -> 0.0501572 | U6: =IFERROR(AVERAGE(D6:L6),0) -> 0.081760841 | V6: =IFERROR(MEDIAN(C6:L6),0) -> 0.063470538
B7: NET PROFIT GROWTH | C7: - | D7: =IFERROR('Profit & Loss'!C21/'Profit & Loss'!B21-1,0) -> 0.11677001 | E7: =IFERROR('Profit & Loss'!D21/'Profit & Loss'!C21-1,0) -> -0.038617506 | F7: =IFERROR('Profit & Loss'!E21/'Profit & Loss'!D21-1,0) -> 0.079753407 | G7: =IFERROR('Profit & Loss'!F21/'Profit & Loss'!E21-1,0) -> 0.16731775 | H7: =IFERROR('Profit & Loss'!G21/'Profit & Loss'!F21-1,0) -> 0.14019461 | I7: =IFERROR('Profit & Loss'!H21/'Profit & Loss'!G21-1,0) -> 0.088593877 | J7: =IFERROR('Profit & Loss'!I21/'Profit & Loss'!H21-1,0) -> 0.088767214 | K7: =IFERROR('Profit & Loss'!J21/'Profit & Loss'!I21-1,0) -> 0.019125267 | ... Q7: =IFERROR('Profit & Loss'!P21/'Profit & Loss'!O21-1,0) -> 0.048869965 | U7: =IFERROR(AVERAGE(D7:L7),0) -> 0.084859601 | V7: =IFERROR(MEDIAN(C7:L7),0) -> 0.088767214
B8: DIVIDEND GROWTH | C8: - | D8: =IFERROR('Profit & Loss'!C32/'Profit & Loss'!B32-1,0) -> 0.68963897 | E8: =IFERROR('Profit & Loss'!D32/'Profit & Loss'!C32-1,0) -> -0.02583858 | F8: =IFERROR('Profit & Loss'!E32/'Profit & Loss'!D32-1,0) -> -0.17390646 | G8: =IFERROR('Profit & Loss'!F32/'Profit & Loss'!E32-1,0) -> 0.54369512 | H8: =IFERROR('Profit & Loss'!G32/'Profit & Loss'!F32-1,0) -> 0.14865158 | I8: =IFERROR('Profit & Loss'!H32/'Profit & Loss'!G32-1,0) -> 0.096761529 | J8: =IFERROR('Profit & Loss'!I32/'Profit & Loss'!H32-1,0) -> 0.35349861 | K8: =IFERROR('Profit & Loss'!J32/'Profit & Loss'!I32-1,0) -> -0.064855345 | ... Q8: =IFERROR('Profit & Loss'!P32/'Profit & Loss'!O32-1,0) -> 0.062685596 | U8: =IFERROR(AVERAGE(D8:L8),0) -> 0.18708827 | V8: =IFERROR(MEDIAN(C8:L8),0) -> 0.116149
B11: GROSS MARGIN | C11: =IFERROR('Profit & Loss'!B60,0) -> 0.39315753 | D11: =IFERROR('Profit & Loss'!C60,0) -> 0.38907008 | E11: =IFERROR('Profit & Loss'!D60,0) -> 0.36420925 | F11: =IFERROR('Profit & Loss'!E60,0) -> 0.34567303 | G11: =IFERROR('Profit & Loss'!F60,0) -> 0.34022414 | H11: =IFERROR('Profit & Loss'!G60,0) -> 0.32157743 | I11: =IFERROR('Profit & Loss'!H60,0) -> 0.30380126 | J11: =IFERROR('Profit & Loss'!I60,0) -> 0.31464176 | ... Q11: =IFERROR('Profit & Loss'!P60,0) -> 0.28435351 | U11: =IFERROR(AVERAGE(C11:L11),0) -> 0.33782065 | V11: =IFERROR(MEDIAN(C11:L11),0) -> 0.33090079
B12: EBITDA MARGIN | C12: =IFERROR('Profit & Loss'!B59,0) -> 0.31619064 | D12: =IFERROR('Profit & Loss'!C59,0) -> 0.31384532 | E12: =IFERROR('Profit & Loss'!D59,0) -> 0.27882673 | F12: =IFERROR('Profit & Loss'!E59,0) -> 0.27612869 | G12: =IFERROR('Profit & Loss'!F59,0) -> 0.29948642 | H12: =IFERROR('Profit & Loss'!G59,0) -> 0.27775174 | I12: =IFERROR('Profit & Loss'!H59,0) -> 0.2577623 | J12: =IFERROR('Profit & Loss'!I59,0) -> 0.26769051 | ... Q12: =IFERROR('Profit & Loss'!P59,0) -> 0.24868675 | U12: =IFERROR(AVERAGE(C12:L12),0) -> 0.28041372 | V12: =IFERROR(MEDIAN(C12:L12),0) -> 0.27694022
B13: EBIT MARGIN | C13: =IFERROR((Annual[[#This Row],[Column2]]-'Profit & Loss'!B15)/'Profit & Loss'!B4,0) -> -0.024867122 | D13: =IFERROR((Annual[[#This Row],[Column3]]-'Profit & Loss'!C15)/'Profit & Loss'!C4,0) -> -0.026417288 | E13: =IFERROR((Annual[[#This Row],[Column4]]-'Profit & Loss'!D15)/'Profit & Loss'!D4,0) -> -0.024324161 | F13: =IFERROR((Annual[[#This Row],[Column5]]-'Profit & Loss'!E15)/'Profit & Loss'!E4,0) -> -0.031864392 | G13: =IFERROR((Annual[[#This Row],[Column6]]-'Profit & Loss'!F15)/'Profit & Loss'!F4,0) -> -0.032516522 | H13: =IFERROR((Annual[[#This Row],[Column7]]-'Profit & Loss'!G15)/'Profit & Loss'!G4,0) -> -0.028575891 | I13: =IFERROR((Annual[[#This Row],[Column8]]-'Profit & Loss'!H15)/'Profit & Loss'!H4,0) -> -0.028787125 | J13: =IFERROR((Annual[[#This Row],[Column9]]-'Profit & Loss'!I15)/'Profit & Loss'!I4,0) -> -0.030441856 | K13: =IFERROR((Annual[[#This Row],[Column10]]-'Profit & Loss'!J15)/'Profit & Loss'!J4,0) -> -0.029523284 | L13: =IFERROR((Annual[[#This Row],[Column11]]-'Profit & Loss'!K15)/'Profit & Loss'!K4,0) -> -0.027439127 | M13: =IFERROR((Annual[[#This Row],[Column12]]-'Profit & Loss'!L15)/'Profit & Loss'!L4,0) -> -0.029488723 | N13: =IFERROR((Annual[[#This Row],[Column13]]-'Profit & Loss'!M15)/'Profit & Loss'!M4,0) -> -0.029566238 | O13: =IFERROR((Annual[[#This Row],[Column14]]-'Profit & Loss'!N15)/'Profit & Loss'!N4,0) -> -0.029634297 | P13: =IFERROR((Annual[[#This Row],[Column15]]-'Profit & Loss'!O15)/'Profit & Loss'!O4,0) -> -0.02969453 | Q13: =IFERROR((Annual[[#This Row],[Column12]]-'Profit & Loss'!P15)/'Profit & Loss'!P4,0) -> -0.029748215 | U13: =IFERROR(AVERAGE(C13:L13),0) -> -0.028475677 | V13: =IFERROR(MEDIAN(C13:L13),0) -> -0.028681508
B14: EBT MARGIN | C14: =IFERROR('Profit & Loss'!B62,0) -> 0.29132352 | D14: =IFERROR('Profit & Loss'!C62,0) -> 0.28742804 | E14: =IFERROR('Profit & Loss'!D62,0) -> 0.25450257 | F14: =IFERROR('Profit & Loss'!E62,0) -> 0.24239187 | G14: =IFERROR('Profit & Loss'!F62,0) -> 0.26502906 | H14: =IFERROR('Profit & Loss'!G62,0) -> 0.24753167 | I14: =IFERROR('Profit & Loss'!H62,0) -> 0.22704014 | J14: =IFERROR('Profit & Loss'!I62,0) -> 0.23419015 | ... Q14: =IFERROR('Profit & Loss'!P62,0) -> 0.21584167 | U14: =IFERROR(AVERAGE(C14:L14),0) -> 0.25040486 | V14: =IFERROR(MEDIAN(C14:L14),0) -> 0.24496177
B15: NET PROFIT MARGIN | C15: =IFERROR('Profit & Loss'!B63,0) -> 0.2095818 | D15: =IFERROR('Profit & Loss'!C63,0) -> 0.22729077 | E15: =IFERROR('Profit & Loss'!D63,0) -> 0.1863925 | F15: =IFERROR('Profit & Loss'!E63,0) -> 0.18326706 | G15: =IFERROR('Profit & Loss'!F63,0) -> 0.19331754 | H15: =IFERROR('Profit & Loss'!G63,0) -> 0.18206033 | I15: =IFERROR('Profit & Loss'!H63,0) -> 0.16426036 | J15: =IFERROR('Profit & Loss'!I63,0) -> 0.17080757 | ... Q15: =IFERROR('Profit & Loss'!P63,0) -> 0.15525787 | U15: =IFERROR(AVERAGE(C15:L15),0) -> 0.18460802 | V15: =IFERROR(MEDIAN(C15:L15),0) -> 0.18266369
B20: SALES EXPENSES%SALES | C20: =IFERROR('Profit & Loss'!B12/'Profit & Loss'!B4,0) -> 0.076966883 | D20: =IFERROR('Profit & Loss'!C12/'Profit & Loss'!C4,0) -> 0.075224753 | E20: =IFERROR('Profit & Loss'!D12/'Profit & Loss'!D4,0) -> 0.085382522 | F20: =IFERROR('Profit & Loss'!E12/'Profit & Loss'!E4,0) -> 0.069544338 | G20: =IFERROR('Profit & Loss'!F12/'Profit & Loss'!F4,0) -> 0.040737718 | H20: =IFERROR('Profit & Loss'!G12/'Profit & Loss'!G4,0) -> 0.043825684 | I20: =IFERROR('Profit & Loss'!H12/'Profit & Loss'!H4,0) -> 0.04603896 | J20: =IFERROR('Profit & Loss'!I12/'Profit & Loss'!I4,0) -> 0.046951259 | ... Q20: =IFERROR('Profit & Loss'!P12/'Profit & Loss'!P4,0) -> 0.035666761 | U20: =IFERROR(AVERAGE(C20:L20),0) -> 0.057406923 | V20: =IFERROR(MEDIAN(C20:L20),0) -> 0.046495109
B21: DEPRECIATION%SALES | C21: =IFERROR('Profit & Loss'!B15/'Profit & Loss'!B4,0) -> 0.024867122 | D21: =IFERROR('Profit & Loss'!C15/'Profit & Loss'!C4,0) -> 0.026417288 | E21: =IFERROR('Profit & Loss'!D15/'Profit & Loss'!D4,0) -> 0.024324161 | F21: =IFERROR('Profit & Loss'!E15/'Profit & Loss'!E4,0) -> 0.031864392 | G21: =IFERROR('Profit & Loss'!F15/'Profit & Loss'!F4,0) -> 0.032516522 | H21: =IFERROR('Profit & Loss'!G15/'Profit & Loss'!G4,0) -> 0.028575891 | I21: =IFERROR('Profit & Loss'!H15/'Profit & Loss'!H4,0) -> 0.028787125 | J21: =IFERROR('Profit & Loss'!I15/'Profit & Loss'!I4,0) -> 0.030441856 | ... Q21: =IFERROR('Profit & Loss'!P15/'Profit & Loss'!P4,0) -> 0.029748215 | U21: =IFERROR(AVERAGE(C21:L21),0) -> 0.028475677 | V21: =IFERROR(MEDIAN(C21:L21),0) -> 0.028681508
B22: OPERATING INCOME%SALES | C22: =C13 -> -0.024867122 | D22: =D13 -> -0.026417288 | E22: =E13 -> -0.024324161 | F22: =F13 -> -0.031864392 | G22: =G13 -> -0.032516522 | H22: =H13 -> -0.028575891 | I22: =I13 -> -0.028787125 | J22: =J13 -> -0.030441856 | ... Q22: =Q13 -> -0.029748215 | U22: =IFERROR(AVERAGE(C22:L22),0) -> -0.028475677 | V22: =IFERROR(MEDIAN(C22:L22),0) -> -0.028681508
B25: RETURN ON CAPITAL EMPLOYEE | C25: =IFERROR(('Profit & Loss'!B14-'Profit & Loss'!B15)/SUM('Balance Sheet'!B4:B6),0) -> 0.28922038 | D25: =IFERROR(('Profit & Loss'!C14-'Profit & Loss'!C15)/SUM('Balance Sheet'!C4:C6),0) -> 0.31221601 | E25: =IFERROR(('Profit & Loss'!D14-'Profit & Loss'!D15)/SUM('Balance Sheet'!D4:D6),0) -> 0.32396687 | F25: =IFERROR(('Profit & Loss'!E14-'Profit & Loss'!E15)/SUM('Balance Sheet'!E4:E6),0) -> 0.31643908 | G25: =IFERROR(('Profit & Loss'!F14-'Profit & Loss'!F15)/SUM('Balance Sheet'!F4:F6),0) -> 0.32840737 | H25: =IFERROR(('Profit & Loss'!G14-'Profit & Loss'!G15)/SUM('Balance Sheet'!G4:G6),0) -> 0.37501237 | I25: =IFERROR(('Profit & Loss'!H14-'Profit & Loss'!H15)/SUM('Balance Sheet'!H4:H6),0) -> 0.4014766 | J25: =IFERROR(('Profit & Loss'!I14-'Profit & Loss'!I15)/SUM('Balance Sheet'!I4:I6),0) -> 0.37790101 | ... Q25: =IFERROR(('Profit & Loss'!P14-'Profit & Loss'!P15)/SUM('Balance Sheet'!P4:P6),0) -> 0.42270335 | U25: =IFERROR(AVERAGE(C25:L25),0) -> 0.34861745 | V25: =IFERROR(MEDIAN(C25:L25),0) -> 0.34693231
B26: RETAINED EARNINGS% | C26: =IFERROR('Profit & Loss'!B35,0) -> 0.58952135 | D26: =IFERROR('Profit & Loss'!C35,0) -> 0.40947034 | E26: =IFERROR('Profit & Loss'!D35,0) -> 0.40152498 | F26: =IFERROR('Profit & Loss'!E35,0) -> 0.55363904 | G26: =IFERROR('Profit & Loss'!F35,0) -> 0.4094836 | H26: =IFERROR('Profit & Loss'!G35,0) -> 0.41264337 | I26: =IFERROR('Profit & Loss'!H35,0) -> 0.41640949 | J26: =IFERROR('Profit & Loss'!I35,0) -> 0.2741085 | ... Q26: =IFERROR('Profit & Loss'!P35,0) -> 0.28170351 | U26: =IFERROR(AVERAGE(C26:L26),0) -> 0.41411022 | V26: =IFERROR(MEDIAN(C26:L26),0) -> 0.40947697
B27: RETURN ON EQUITY% | C27: =IFERROR('Profit & Loss'!B21/SUM('Balance Sheet'!B4:B5),0) -> 0.20806877 | D27: =IFERROR('Profit & Loss'!C21/SUM('Balance Sheet'!C4:C5),0) -> 0.24689247 | E27: =IFERROR('Profit & Loss'!D21/SUM('Balance Sheet'!D4:D5),0) -> 0.23726674 | F27: =IFERROR('Profit & Loss'!E21/SUM('Balance Sheet'!E4:E5),0) -> 0.2542246 | G27: =IFERROR('Profit & Loss'!F21/SUM('Balance Sheet'!F4:F5),0) -> 0.25439091 | H27: =IFERROR('Profit & Loss'!G21/SUM('Balance Sheet'!G4:G5),0) -> 0.29390843 | I27: =IFERROR('Profit & Loss'!H21/SUM('Balance Sheet'!H4:H5),0) -> 0.31970507 | J27: =IFERROR('Profit & Loss'!I21/SUM('Balance Sheet'!I4:I5),0) -> 0.29788007 | ... Q27: =IFERROR('Profit & Loss'!P21/SUM('Balance Sheet'!P4:P5),0) -> 0.34355278 | U27: =IFERROR(AVERAGE(C27:L27),0) -> 0.2708942 | V27: =IFERROR(MEDIAN(C27:L27),0) -> 0.266783
B28: SELF SUSTAINED GROWTH RATE | C28: =IFERROR(C26*C27,0) -> 0.12266098 | D28: =IFERROR(D26*D27,0) -> 0.10109514 | E28: =IFERROR(E26*E27,0) -> 0.095268523 | F28: =IFERROR(F26*F27,0) -> 0.14074866 | G28: =IFERROR(G26*G27,0) -> 0.1041689 | H28: =IFERROR(H26*H27,0) -> 0.12127936 | I28: =IFERROR(I26*I27,0) -> 0.13312822 | J28: =IFERROR(J26*J27,0) -> 0.081651459 | ... Q28: =IFERROR(Q26*Q27,0) -> 0.096780027 | U28: =IFERROR(AVERAGE(C28:L28),0) -> 0.11012852 | V28: =IFERROR(MEDIAN(C28:L28),0) -> 0.10616837
B29: INTEREST COVERAGE RATIO | C29: =IFERROR(('Profit & Loss'!B14-'Profit & Loss'!B15)/'Profit & Loss'!B16,0) -> 0 | D29: =IFERROR(('Profit & Loss'!C14-'Profit & Loss'!C15)/'Profit & Loss'!C16,0) -> 0 | E29: =IFERROR(('Profit & Loss'!D14-'Profit & Loss'!D15)/'Profit & Loss'!D16,0) -> 0 | F29: =IFERROR(('Profit & Loss'!E14-'Profit & Loss'!E15)/'Profit & Loss'!E16,0) -> 130.45294 | G29: =IFERROR(('Profit & Loss'!F14-'Profit & Loss'!F15)/'Profit & Loss'!F16,0) -> 137.55385 | H29: =IFERROR(('Profit & Loss'!G14-'Profit & Loss'!G15)/'Profit & Loss'!G16,0) -> 151.55 | I29: =IFERROR(('Profit & Loss'!H14-'Profit & Loss'!H15)/'Profit & Loss'!H16,0) -> 118.33099 | J29: =IFERROR(('Profit & Loss'!I14-'Profit & Loss'!I15)/'Profit & Loss'!I16,0) -> 77.570213 | ... Q29: =IFERROR(('Profit & Loss'!P14-'Profit & Loss'!P15)/'Profit & Loss'!P16,0) -> 70.696876 | U29: =IFERROR(AVERAGE(C29:L29),0) -> 80.400366 | V29: =IFERROR(MEDIAN(C29:L29),0) -> 94.272837
B32: DEBTOR TURNOVER RATIO | C32: =IFERROR('Profit & Loss'!B4/'Balance Sheet'!B16,0) -> 5.557864 | D32: =IFERROR('Profit & Loss'!C4/'Balance Sheet'!C16,0) -> 5.3661543 | E32: =IFERROR('Profit & Loss'!D4/'Balance Sheet'!D16,0) -> 5.5759763 | F32: =IFERROR('Profit & Loss'!E4/'Balance Sheet'!E16,0) -> 4.9110726 | G32: =IFERROR('Profit & Loss'!F4/'Balance Sheet'!F16,0) -> 5.207422 | H32: =IFERROR('Profit & Loss'!G4/'Balance Sheet'!G16,0) -> 5.3591065 | I32: =IFERROR('Profit & Loss'!H4/'Balance Sheet'!H16,0) -> 5.7727738 | J32: =IFERROR('Profit & Loss'!I4/'Balance Sheet'!I16,0) -> 5.0895903 | ... Q32: =IFERROR('Profit & Loss'!P4/'Balance Sheet'!P16,0) -> 0 | U32: =IFERROR(AVERAGE(C32:L32),0) -> 5.3141427 | V32: =IFERROR(MEDIAN(C32:L32),0) -> 5.2950934
B33: CREDITOR TURNOVER RATIO | C33: =IFERROR('Profit & Loss'!B4/'Balance Sheet'!B7,0) -> 4.8343922 | D33: =IFERROR('Profit & Loss'!C4/'Balance Sheet'!C7,0) -> 4.8885346 | E33: =IFERROR('Profit & Loss'!D4/'Balance Sheet'!D7,0) -> 4.3244586 | F33: =IFERROR('Profit & Loss'!E4/'Balance Sheet'!E7,0) -> 4.1806419 | G33: =IFERROR('Profit & Loss'!F4/'Balance Sheet'!F7,0) -> 3.8889878 | H33: =IFERROR('Profit & Loss'!G4/'Balance Sheet'!G7,0) -> 3.3878568 | I33: =IFERROR('Profit & Loss'!H4/'Balance Sheet'!H7,0) -> 3.5893128 | J33: =IFERROR('Profit & Loss'!I4/'Balance Sheet'!I7,0) -> 3.8859527 | ... Q33: =IFERROR('Profit & Loss'!P4/'Balance Sheet'!P7,0) -> 3.3755126 | U33: =IFERROR(AVERAGE(C33:L33),0) -> 4.0124108 | V33: =IFERROR(MEDIAN(C33:L33),0) -> 3.8874703
B34: INVENTORY TURNOVER | C34: =IFERROR('Profit & Loss'!B4/'Balance Sheet'!B17,0) -> 0 | D34: =IFERROR('Profit & Loss'!C4/'Balance Sheet'!C17,0) -> 0 | E34: =IFERROR('Profit & Loss'!D4/'Balance Sheet'!D17,0) -> 0 | F34: =IFERROR('Profit & Loss'!E4/'Balance Sheet'!E17,0) -> 0 | G34: =IFERROR('Profit & Loss'!F4/'Balance Sheet'!F17,0) -> 0 | H34: =IFERROR('Profit & Loss'!G4/'Balance Sheet'!G17,0) -> 0 | I34: =IFERROR('Profit & Loss'!H4/'Balance Sheet'!H17,0) -> 0 | J34: =IFERROR('Profit & Loss'!I4/'Balance Sheet'!I17,0) -> 0 | ... Q34: =IFERROR('Profit & Loss'!P4/'Balance Sheet'!P17,0) -> 0 | U34: =IFERROR(AVERAGE(C34:L34),0) -> 0 | V34: =IFERROR(MEDIAN(C34:L34),0) -> 0
B35: FIXED ASSEST TURNOVER | C35: =IFERROR('Profit & Loss'!B4/'Balance Sheet'!B10,0) -> 4.8299598 | D35: =IFERROR('Profit & Loss'!C4/'Balance Sheet'!C10,0) -> 5.6085573 | E35: =IFERROR('Profit & Loss'!D4/'Balance Sheet'!D10,0) -> 5.2625716 | F35: =IFERROR('Profit & Loss'!E4/'Balance Sheet'!E10,0) -> 3.8165118 | G35: =IFERROR('Profit & Loss'!F4/'Balance Sheet'!F10,0) -> 3.939306 | H35: =IFERROR('Profit & Loss'!G4/'Balance Sheet'!G10,0) -> 4.7147674 | I35: =IFERROR('Profit & Loss'!H4/'Balance Sheet'!H10,0) -> 5.0219675 | J35: =IFERROR('Profit & Loss'!I4/'Balance Sheet'!I10,0) -> 5.5633191 | ... Q35: =IFERROR('Profit & Loss'!P4/'Balance Sheet'!P10,0) -> 5.3061582 | U35: =IFERROR(AVERAGE(C35:L35),0) -> 4.9311524 | V35: =IFERROR(MEDIAN(C35:L35),0) -> 5.1422696
B36: CAPITAL TURNOVER RATIO | C36: =IFERROR('Profit & Loss'!B4/SUM('Balance Sheet'!B4:B5),0) -> 0.99278073 | D36: =IFERROR('Profit & Loss'!C4/SUM('Balance Sheet'!C4:C5),0) -> 1.0862406 | E36: =IFERROR('Profit & Loss'!D4/SUM('Balance Sheet'!D4:D5),0) -> 1.2729414 | F36: =IFERROR('Profit & Loss'!E4/SUM('Balance Sheet'!E4:E5),0) -> 1.3871811 | G36: =IFERROR('Profit & Loss'!F4/SUM('Balance Sheet'!F4:F5),0) -> 1.3159225 | H36: =IFERROR('Profit & Loss'!G4/SUM('Balance Sheet'!G4:G5),0) -> 1.6143464 | I36: =IFERROR('Profit & Loss'!H4/SUM('Balance Sheet'!H4:H5),0) -> 1.9463312 | J36: =IFERROR('Profit & Loss'!I4/SUM('Balance Sheet'!I4:I5),0) -> 1.7439512 | ... Q36: =IFERROR('Profit & Loss'!P4/SUM('Balance Sheet'!P4:P5),0) -> 2.2127882 | U36: =IFERROR(AVERAGE(C36:L36),0) -> 1.4984762 | V36: =IFERROR(MEDIAN(C36:L36),0) -> 1.5007637
B39: DEBTOR DAYS | C39: =IFERROR(365/C32,0) -> 65.672712 | D39: =IFERROR(365/D32,0) -> 68.018916 | E39: =IFERROR(365/E32,0) -> 65.459389 | F39: =IFERROR(365/F32,0) -> 74.321849 | G39: =IFERROR(365/G32,0) -> 70.092265 | H39: =IFERROR(365/H32,0) -> 68.108368 | I39: =IFERROR(365/I32,0) -> 63.227837 | J39: =IFERROR(365/J32,0) -> 71.715006 | ... Q39: =IFERROR(365/Q32,0) -> 0 | U39: =IFERROR(AVERAGE(C39:L39),0) -> 68.837823 | V39: =IFERROR(MEDIAN(C39:L39),0) -> 68.941815
B40: PAYABLE DAYS | C40: =IFERROR(365/C33,0) -> 75.500701 | D40: =IFERROR(365/D33,0) -> 74.664502 | E40: =IFERROR(365/E33,0) -> 84.403629 | F40: =IFERROR(365/F33,0) -> 87.307167 | G40: =IFERROR(365/G33,0) -> 93.854756 | H40: =IFERROR(365/H33,0) -> 107.73773 | I40: =IFERROR(365/I33,0) -> 101.69078 | J40: =IFERROR(365/J33,0) -> 93.92806 | ... Q40: =IFERROR(365/Q33,0) -> 108.13172 | U40: =IFERROR(AVERAGE(C40:L40),0) -> 92.383358 | V40: =IFERROR(MEDIAN(C40:L40),0) -> 93.891408
B41: INVENTORY DAYS | C41: =IFERROR(365/C34,0) -> 0 | D41: =IFERROR(365/D34,0) -> 0 | E41: =IFERROR(365/E34,0) -> 0 | F41: =IFERROR(365/F34,0) -> 0 | G41: =IFERROR(365/G34,0) -> 0 | H41: =IFERROR(365/H34,0) -> 0 | I41: =IFERROR(365/I34,0) -> 0 | J41: =IFERROR(365/J34,0) -> 0 | ... Q41: =IFERROR(365/Q34,0) -> 0 | U41: =IFERROR(AVERAGE(C41:L41),0) -> 0 | V41: =IFERROR(MEDIAN(C41:L41),0) -> 0
B42: CASH CONVERSION CYCLE | C42: =SUM(C39+C41)-C40 -> -9.827989 | D42: =SUM(D39+D41)-D40 -> -6.6455858 | E42: =SUM(E39+E41)-E40 -> -18.944239 | F42: =SUM(F39+F41)-F40 -> -12.985318 | G42: =SUM(G39+G41)-G40 -> -23.762491 | H42: =SUM(H39+H41)-H40 -> -39.62936 | I42: =SUM(I39+I41)-I40 -> -38.462938 | J42: =SUM(J39+J41)-J40 -> -22.213054 | ... Q42: =SUM(Q39+Q41)-Q40 -> -108.13172 | U42: =IFERROR(AVERAGE(C42:L42),0) -> -23.545535 | V42: =IFERROR(MEDIAN(C42:L42),0) -> -22.987772
B45: CFO/SALES | C45: =IFERROR('Cash Flow'!B5/'Profit & Loss'!B4,0) -> 0.16837509 | D45: =IFERROR('Cash Flow'!C5/'Profit & Loss'!C4,0) -> 0.18743087 | E45: =IFERROR('Cash Flow'!D5/'Profit & Loss'!D4,0) -> 0.17951013 | F45: =IFERROR('Cash Flow'!E5/'Profit & Loss'!E4,0) -> 0.18727627 | G45: =IFERROR('Cash Flow'!F5/'Profit & Loss'!F4,0) -> 0.23114898 | H45: =IFERROR('Cash Flow'!G5/'Profit & Loss'!G4,0) -> 0.19635649 | I45: =IFERROR('Cash Flow'!H5/'Profit & Loss'!H4,0) -> 0.15307937 | J45: =IFERROR('Cash Flow'!I5/'Profit & Loss'!I4,0) -> 0.16405284 | ... Q45: =IFERROR('Cash Flow'!P5/'Profit & Loss'!P4,0) -> 0.1921841 | U45: =IFERROR(AVERAGE(C45:L45),0) -> 0.1876463 | V45: =IFERROR(MEDIAN(C45:L45),0) -> 0.18735357
B46: CFO/TOTAL ASSESTS | C46: =IFERROR('Cash Flow'!B5/'Balance Sheet'!B19,0) -> 0.32995679 | D46: =IFERROR('Cash Flow'!C5/'Balance Sheet'!C19,0) -> 0.40103155 | E46: =IFERROR('Cash Flow'!D5/'Balance Sheet'!D19,0) -> 0.43148713 | F46: =IFERROR('Cash Flow'!E5/'Balance Sheet'!E19,0) -> 0.4578576 | G46: =IFERROR('Cash Flow'!F5/'Balance Sheet'!F19,0) -> 0.52772223 | H46: =IFERROR('Cash Flow'!G5/'Balance Sheet'!G19,0) -> 0.59459796 | I46: =IFERROR('Cash Flow'!H5/'Balance Sheet'!H19,0) -> 0.59757427 | J46: =IFERROR('Cash Flow'!I5/'Balance Sheet'!I19,0) -> 0.56048378 | ... Q46: =IFERROR('Cash Flow'!P5/'Balance Sheet'!P19,0) -> 2.5440288 | U46: =IFERROR(AVERAGE(C46:L46),0) -> 0.51342695 | V46: =IFERROR(MEDIAN(C46:L46),0) -> 0.54410301
B47: CFO/TOTAL DEBT | C47: =IFERROR('Cash Flow'!B5/'Balance Sheet'!B6,0) -> 0 | D47: =IFERROR('Cash Flow'!C5/'Balance Sheet'!C6,0) -> 0 | E47: =IFERROR('Cash Flow'!D5/'Balance Sheet'!D6,0) -> 0 | F47: =IFERROR('Cash Flow'!E5/'Balance Sheet'!E6,0) -> 3.6699763 | G47: =IFERROR('Cash Flow'!F5/'Balance Sheet'!F6,0) -> 4.3613146 | H47: =IFERROR('Cash Flow'!G5/'Balance Sheet'!G6,0) -> 4.363354 | I47: =IFERROR('Cash Flow'!H5/'Balance Sheet'!H6,0) -> 2.7071936 | J47: =IFERROR('Cash Flow'!I5/'Balance Sheet'!I6,0) -> 3.015911 | ... Q47: =IFERROR('Cash Flow'!P5/'Balance Sheet'!P6,0) -> 2.9105622 | U47: =IFERROR(AVERAGE(C47:L47),0) -> 2.6160183 | V47: =IFERROR(MEDIAN(C47:L47),0) -> 3.3429436

Sheet FORECASTING
B2: SALES | G2: EBITDA | L2: EPS
B4: YEAR WEIGHT | C4: YEAR | D4: SALES | E4: SALES GROWTH | G4: YEAR WEIGHT | H4: YEAR | I4: EBITDA | J4: EBITDA GROWTH | L4: YEAR WEIGHT | M4: YEAR | N4: EPS | O4: EPS GROWTH
B5: 1 | C5: ='Data Sheet'!$B$16 -> 42825 | D5: {=TRANSPOSE('Data Sheet'!B17:K17)} -> 68484 | G5: 1 | H5: ='Data Sheet'!$B$16 -> 42825 | I5: {=TRANSPOSE('Profit & Loss'!B14:K14)} -> 21654 | L5: 1 | M5: ='Data Sheet'!$B$16 -> 42825 | N5: {=TRANSPOSE('Profit & Loss'!B25:K25)} -> 31.243606
B6: =B5+1 -> 2 | C6: =C5+365 -> 43190 | D6: 70522 | E6: =IFERROR(D6/D5-1,0) -> 0.029758776 | G6: =G5+1 -> 2 | H6: =H5+365 -> 43190 | I6: 22133 | J6: =IFERROR(I6/I5-1,0) -> 0.022120624 | L6: =L5+1 -> 2 | M6: =M5+365 -> 43190 | N6: 36.694748 | O6: =IFERROR(N6/N5-1,0) -> 0.17447227
B7: =B6+1 -> 3 | C7: =C6+365 -> 43555 | D7: 82675 | E7: =IFERROR(D7/D6-1,0) -> 0.1723292 | G7: =G6+1 -> 3 | H7: =H6+365 -> 43555 | I7: 23052 | J7: =IFERROR(I7/I6-1,0) -> 0.04152171 | L7: =L6+1 -> 3 | M7: =M6+365 -> 43555 | N7: 35.272036 | O7: =IFERROR(N7/N6-1,0) -> -0.038771542
B8: =B7+1 -> 4 | C8: =C7+365 -> 43920 | D8: 90791 | E8: =IFERROR(D8/D7-1,0) -> 0.098167523 | G8: =G7+1 -> 4 | H8: =H7+365 -> 43920 | I8: 25070 | J8: =IFERROR(I8/I7-1,0) -> 0.087541211 | L8: =L7+1 -> 4 | M8: =M7+365 -> 43920 | N8: 39.067856 | O8: =IFERROR(N8/N7-1,0) -> 0.10761556
B9: =B8+1 -> 5 | C9: =C8+365 -> 44285 | D9: 100472 | E9: =IFERROR(D9/D8-1,0) -> 0.10662951 | G9: =G8+1 -> 5 | H9: =H8+365 -> 44285 | I9: 30090 | J9: =IFERROR(I9/I8-1,0) -> 0.20023933 | L9: =L8+1 -> 5 | M9: =M8+365 -> 44285 | N9: 45.586406 | O9: =IFERROR(N9/N8-1,0) -> 0.16685199
B10: =B9+1 -> 6 | C10: =C9+365 -> 44650 | D10: 121641 | E10: =IFERROR(D10/D9-1,0) -> 0.21069552 | G10: =G9+1 -> 6 | H10: =H9+365 -> 44650 | I10: 33786 | J10: =IFERROR(I10/I9-1,0) -> 0.12283151 | L10: =L9+1 -> 6 | M10: =M9+365 -> 44650 | N10: 52.644591 | O10: =IFERROR(N10/N9-1,0) -> 0.15483091
B11: =B10+1 -> 7 | C11: =C10+365 -> 45015 | D11: 146767 | E11: =IFERROR(D11/D10-1,0) -> 0.20655864 | G11: =G10+1 -> 7 | H11: =H10+365 -> 45015 | I11: 37831 | J11: =IFERROR(I11/I10-1,0) -> 0.11972415 | L11: =L10+1 -> 7 | M11: =M10+365 -> 45015 | N11: 58.11117 | O11: =IFERROR(N11/N10-1,0) -> 0.10383933
B12: =B11+1 -> 8 | C12: =C11+365 -> 45380 | D12: 153670 | E12: =IFERROR(D12/D11-1,0) -> 0.047033734 | G12: =G11+1 -> 8 | H12: =H11+365 -> 45380 | I12: 41136 | J12: =IFERROR(I12/I11-1,0) -> 0.087362216 | L12: =L11+1 -> 8 | M12: =M11+365 -> 45380 | N12: 63.234479 | O12: =IFERROR(N12/N11-1,0) -> 0.088163932
B13: =B12+1 -> 9 | C13: =C12+365 -> 45745 | D13: 162990 | E13: =IFERROR(D13/D12-1,0) -> 0.060649444 | G13: =G12+1 -> 9 | H13: =H12+365 -> 45745 | I13: 42836 | J13: =IFERROR(I13/I12-1,0) -> 0.041326332 | L13: =L12+1 -> 9 | M13: =M12+365 -> 45745 | N13: 64.406616 | O13: =IFERROR(N13/N12-1,0) -> 0.018536361
B14: =B13+1 -> 10 | C14: =C13+365 -> 46110 | D14: 178650 | E14: =IFERROR(D14/D13-1,0) -> 0.096079514 | G14: =G13+1 -> 10 | H14: =H13+365 -> 46110 | I14: 45313 | J14: =IFERROR(I14/I13-1,0) -> 0.057825194 | L14: =L13+1 -> 10 | M14: =M13+365 -> 46110 | N14: 72.67482 | O14: =IFERROR(N14/N13-1,0) -> 0.12837507
B15: =B14+1 -> 11 | C15: =C14+365 -> 46475 | D15: =FORECAST(B15,$D$5:$D$14,$B$5:$B$14) -> 190427.6 | E15: =IFERROR(D15/D14-1,0) -> 0.065925553 | G15: =G14+1 -> 11 | H15: =H14+365 -> 46475 | I15: {=FORECAST(G15,$I$5:$I$14,$G$5:$G$14)} -> 48631.8 | J15: =IFERROR(I15/I14-1,0) -> 0.073241675 | L15: =L14+1 -> 11 | M15: =M14+365 -> 46475 | N15: =FORECAST(L15,$N$5:$N$14,$L$5:$L$14) -> 75.589111 | O15: =IFERROR(N15/N14-1,0) -> 0.040100424
B16: =B15+1 -> 12 | C16: =C15+365 -> 46840 | D16: =FORECAST(B16,$D$5:$D$14,$B$5:$B$14) -> 203656.95 | E16: =IFERROR(D16/D15-1,0) -> 0.069471786 | G16: =G15+1 -> 12 | H16: =H15+365 -> 46840 | I16: {=FORECAST(G16,$I$5:$I$14,$G$5:$G$14)} -> 51603.018 | J16: =IFERROR(I16/I15-1,0) -> 0.0610962 | L16: =L15+1 -> 12 | M16: =M15+365 -> 46840 | N16: =FORECAST(L16,$N$5:$N$14,$L$5:$L$14) -> 80.261016 | O16: =IFERROR(N16/N15-1,0) -> 0.061806589
B17: =B16+1 -> 13 | C17: =C16+365 -> 47205 | D17: =FORECAST(B17,$D$5:$D$14,$B$5:$B$14) -> 216886.29 | E17: =IFERROR(D17/D16-1,0) -> 0.06495897 | G17: =G16+1 -> 13 | H17: =H16+365 -> 47205 | I17: {=FORECAST(G17,$I$5:$I$14,$G$5:$G$14)} -> 54574.236 | J17: =IFERROR(I17/I16-1,0) -> 0.05757838 | L17: =L16+1 -> 13 | M17: =M16+365 -> 47205 | N17: =FORECAST(L17,$N$5:$N$14,$L$5:$L$14) -> 84.932921 | O17: =IFERROR(N17/N16-1,0) -> 0.058208896
B18: =B17+1 -> 14 | C18: =C17+365 -> 47570 | D18: =FORECAST(B18,$D$5:$D$14,$B$5:$B$14) -> 230115.64 | E18: =IFERROR(D18/D17-1,0) -> 0.060996688 | G18: =G17+1 -> 14 | H18: =H17+365 -> 47570 | I18: {=FORECAST(G18,$I$5:$I$14,$G$5:$G$14)} -> 57545.455 | J18: =IFERROR(I18/I17-1,0) -> 0.054443605 | L18: =L17+1 -> 14 | M18: =M17+365 -> 47570 | N18: =FORECAST(L18,$N$5:$N$14,$L$5:$L$14) -> 89.604826 | O18: =IFERROR(N18/N17-1,0) -> 0.055006999
B19: =B18+1 -> 15 | C19: =C18+365 -> 47935 | D19: =FORECAST(B19,$D$5:$D$14,$B$5:$B$14) -> 243344.98 | E19: =IFERROR(D19/D18-1,0) -> 0.057489989 | G19: =G18+1 -> 15 | H19: =H18+365 -> 47935 | I19: {=FORECAST(G19,$I$5:$I$14,$G$5:$G$14)} -> 60516.673 | J19: =IFERROR(I19/I18-1,0) -> 0.051632543 | L19: =L18+1 -> 15 | M19: =M18+365 -> 47935 | N19: =FORECAST(L19,$N$5:$N$14,$L$5:$L$14) -> 94.276732 | O19: =IFERROR(N19/N18-1,0) -> 0.05213899
B23: EXPENSES | G23: 0THER INCOME | L23: SG&A
B25: YEAR WEIGHT | C25: YEAR | D25: EXPENSES | E25: EXPENSES GROWTH | G25: YEAR WEIGHT | H25: YEAR | I25: OTHER INCOME | J25: OTHER INCOME GROWTH | L25: YEAR WEIGHT | M25: YEAR | N25: SG&A | O25: SG&A GROWTH
B26: 1 | C26: ='Data Sheet'!$B$16 -> 42825 | D26: {=TRANSPOSE('Profit & Loss'!B6:K6)} -> 44609 | G26: 1 | H26: ='Data Sheet'!$B$16 -> 42825 | I26: {=TRANSPOSE('Profit & Loss'!B9:K9)} -> 3050 | L26: 1 | M26: ='Data Sheet'!$B$16 -> 42825 | N26: {=TRANSPOSE('Profit & Loss'!B12:K12)} -> 5271
B27: =B26+1 -> 2 | C27: =C26+365 -> 43190 | D27: 46395 | E27: =IFERROR(D27/D26-1,0) -> 0.040036764 | G27: =G26+1 -> 2 | H27: =H26+365 -> 43190 | I27: 3311 | J27: =IFERROR(I27/I26-1,0) -> 0.08557377 | L27: =L26+1 -> 2 | M27: =M26+365 -> 43190 | N27: 5305 | O27: =IFERROR(N27/N26-1,0) -> 0.0064503889
B28: =B27+1 -> 3 | C28: =C27+365 -> 43555 | D28: 55446 | E28: =IFERROR(D28/D27-1,0) -> 0.19508568 | G28: =G27+1 -> 3 | H28: =H27+365 -> 43555 | I28: 2882 | J28: =IFERROR(I28/I27-1,0) -> -0.12956811 | L28: =L27+1 -> 3 | M28: =M27+365 -> 43555 | N28: 7059 | O28: =IFERROR(N28/N27-1,0) -> 0.33063148
B29: =B28+1 -> 4 | C29: =C28+365 -> 43920 | D29: 62210 | E29: =IFERROR(D29/D28-1,0) -> 0.12199257 | G29: =G28+1 -> 4 | H29: =H28+365 -> 43920 | I29: 2803 | J29: =IFERROR(I29/I28-1,0) -> -0.02741152 | L29: =L28+1 -> 4 | M29: =M28+365 -> 43920 | N29: 6314 | O29: =IFERROR(N29/N28-1,0) -> -0.10553903
B30: =B29+1 -> 5 | C30: =C29+365 -> 44285 | D30: 68490 | E30: =IFERROR(D30/D29-1,0) -> 0.1009484 | G30: =G29+1 -> 5 | H30: =H29+365 -> 44285 | I30: 2201 | J30: =IFERROR(I30/I29-1,0) -> -0.21476989 | L30: =L29+1 -> 5 | M30: =M29+365 -> 44285 | N30: 4093 | O30: =IFERROR(N30/N29-1,0) -> -0.351758
B31: =B30+1 -> 6 | C31: =C30+365 -> 44650 | D31: 84819 | E31: =IFERROR(D31/D30-1,0) -> 0.23841437 | G31: =G30+1 -> 6 | H31: =H30+365 -> 44650 | I31: 2295 | J31: =IFERROR(I31/I30-1,0) -> 0.04270786 | L31: =L30+1 -> 6 | M31: =M30+365 -> 44650 | N31: 5331 | O31: =IFERROR(N31/N30-1,0) -> 0.30246763
B32: =B31+1 -> 7 | C32: =C31+365 -> 45015 | D32: 104880 | E32: =IFERROR(D32/D31-1,0) -> 0.2365154 | G32: =G31+1 -> 7 | H32: =H31+365 -> 45015 | I32: 2701 | J32: =IFERROR(I32/I31-1,0) -> 0.17690632 | L32: =L31+1 -> 7 | M32: =M31+365 -> 45015 | N32: 6757 | O32: =IFERROR(N32/N31-1,0) -> 0.26749203
B33: =B32+1 -> 8 | C33: =C32+365 -> 45380 | D33: 110030 | E33: =IFERROR(D33/D32-1,0) -> 0.049103738 | G33: =G32+1 -> 8 | H33: =H32+365 -> 45380 | I33: 4711 | J33: =IFERROR(I33/I32-1,0) -> 0.74416883 | L33: =L32+1 -> 8 | M33: =M32+365 -> 45380 | N33: 7215 | O33: =IFERROR(N33/N32-1,0) -> 0.06778156
B34: =B33+1 -> 9 | C34: =C33+365 -> 45745 | D34: 116585 | E34: =IFERROR(D34/D33-1,0) -> 0.059574661 | G34: =G33+1 -> 9 | H34: =H33+365 -> 45745 | I34: 3600 | J34: =IFERROR(I34/I33-1,0) -> -0.23583103 | L34: =L33+1 -> 9 | M34: =M33+365 -> 45745 | N34: 7169 | O34: =IFERROR(N34/N33-1,0) -> -0.0063756064
B35: =B34+1 -> 10 | C35: =C34+365 -> 46110 | D35: 128257 | E35: =IFERROR(D35/D34-1,0) -> 0.1001158 | G35: =G34+1 -> 10 | H35: =H34+365 -> 46110 | I35: 3033 | J35: =IFERROR(I35/I34-1,0) -> -0.1575 | L35: =L34+1 -> 10 | M35: =M34+365 -> 46110 | N35: 8113 | O35: =IFERROR(N35/N34-1,0) -> 0.13167806
B36: =B35+1 -> 11 | C36: =C35+365 -> 46475 | D36: =FORECAST(B36,$D$26:$D$35,$B$26:$B$35) -> 137552.8 | E36: =IFERROR(D36/D35-1,0) -> 0.072477915 | G36: =G35+1 -> 11 | H36: =H35+365 -> 46475 | I36: =FORECAST(G36,$I$26:$I$35,$G$26:$G$35) -> 3418.8 | J36: =IFERROR(I36/I35-1,0) -> 0.12720079 | L36: =L35+1 -> 11 | M36: =M35+365 -> 46475 | N36: =FORECAST(L36,$N$26:$N$35,$L$26:$L$35) -> 7661.8 | O36: =IFERROR(N36/N35-1,0) -> -0.055614446
